Workbook
Name CODIGOS: #REF!
Name CODIGOS: [1]COLORES!$B$3:$D$49
Name LISTA: #REF!
Name LISTA: #REF!

Sheet POTA ENTERA
E2: REGISTRO DE PESOS POR CUADRILLA | T2: Registro: | U2: SPM-FOT-006 | Z2: LUIS
T3: Versión: | U3: 01 | Z3: FELIX
T4: Fecha: | U4: JULIO-2026 | Z4: CHARLES
B6: DATOS DEL EMPLEADOR
B7: RAZÓN SOCIAL O DENOMINACIÓN SOCIAL | E7: RUC | G7: DOMICILIO (Dirección, Distrito, Provincia, Departamento) | S7: ACTIVIDAD ECONÓMICA | AB7: POTA ENTERA
B8: SOLUCIONES & PROCESOS MARINOS S.A.C. | E8: 2060033416 | G8: Calle a Lote, 04 SI. Sección 5 Ex Fundo Oquendo (Al Km 6.3 Gambeta Espalda Pesquera Bert.) Callao, Provincia Constitucional del Callao, Lima | S8: ELABORACIÓN Y CONSERVACIÓN DE PESCADO, CRUSTÁCEO Y MOLUSCOS | AB8: POTILLA
B10: CLIENTE: | E10: GLOBAL TOP FOOD PERÚ S.A.C. | Q10: LOTE CLIENTE: | T10: 1064PPF150726
B11: PROCESO: | E11: POTA A GRANEL | Q11: FECHA: | U11: 46227
B14: PRODUCTO | C14: POTA ENTERA | E14: POTA ENTERA | G14: POTA ENTERA | I14: POTA ENTERA | K14: POTA ENTERA | M14: POTA ENTERA | O14: POTA ENTERA | Q14: POTA ENTERA | S14: POTA ENTERA | U14: POTA ENTERA
B15: PLACA | C15: M4D-972 | E15: M4B-991 | G15: ATU-890
B16: NUMERO DE CARRO | C16: 1 | E16: 2 | G16: 3 | I16: 4 | K16: 5 | M16: 6 | O16: 7 | Q16: 8 | S16: 9 | U16: 10
B17: CUADRILLA / N° DE DINO | C17: FELIX | D17: LUIS | E17: FELIX | F17: LUIS | G17: FELIX | H17: LUIS | I17: LUIS | J17: CHARLES | K17: FELIX | L17: CHARLES | M17: FELIX | N17: CHARLES | O17: FELIX | P17: CHARLES | Q17: LUIS | R17: CHARLES | S17: LUIS | T17: CHARLES | U17: LUIS | V17: CHARLES
B18: 1 | C18: 542.6 | F18: 541.4
B19: 2 | D19: 519 | E19: 521
B20: 3 | C20: 541.8 | F20: 498.2
B21: 4 | D21: 535.6 | E21: 540.6
B22: 5 | C22: 542.2 | F22: 541.6
B23: 6 | D23: 543 | E23: 524.6
B24: 7 | C24: 518.6 | F24: 539.6
B25: 8 | D25: 541 | E25: 529.8
B26: 9 | C26: 535.2 | F26: 542
B27: 10 | D27: 536 | E27: 536.2
B28: 11 | C28: 539.8 | F28: 542.6
B29: 12 | D29: 531.4 | E29: 519.4
B30: 13 | C30: 541.8 | F30: 524.4
B31: 14 | D31: 542 | E31: 529.8
B32: 15 | C32: 542 | F32: 541.2
B33: 16 | D33: 542 | E33: 537.8
B34: 17 | C34: 541.4 | F34: 525.6
B35: 18 | D35: 539.6 | E35: 511.6
B36: 19 | C36: 542 | F36: 540.4
B37: 20 | D37: 452 | E37: 529.8
B38: 21 | C38: 533.6 | F38: 537.2
B39: 22 | D39: 542.2 | E39: 521.8
B40: 23 | C40: 542.2 | F40: 538.4
B41: 24 | D41: 543 | E41: 542.2
B42: 25 | C42: 543 | F42: 534.2
B43: 26 | D43: 540.6 | E43: 503.6
B44: 27 | C44: 528 | F44: 529.8
B45: 28 | D45: 542 | E45: 542.6
...

Sheet CUADRILLA 1
E2: TAREO DE PERSONAL ÁREA DE FILETEROS | M2: Registro | O2: SPM-FOT-007
M3: Versión | O3: 1
M4: Fecha | O4: JULIO 2026
M5: Página | O5: 1
B7: CLIENTE: | D7: =+'POTA ENTERA'!E10 -> GLOBAL TOP FOOD PERÚ S.A.C. | J7: PRODUCTO: | M7: POTA ENTERA
B8: DÍA / FECHA: | D8: Viernes | F8: / | G8: =+'POTA ENTERA'!U11 -> 46227 | J8: TURNO: | M8: DÍA
B9: HORA INICIO: | E9: 0.29166667 | J9: HORA TERMINO: | N9: 4:25 pm
B10: SUPERVISOR: | D10: OMAR ESCOBEDO | J10: PLACA CARRO:
B13: PESO DE FILETEO POR CUADRILLA
B15: N° | C15: APELLIDOS Y NOMBRES | K15: MENÚ / CENA | M15: TOTAL (PESO) | O15: Importe s/.
B16: 1 | C16: =+'POTA ENTERA'!D81 -> CUADRILLA FELIX | M16: =+'POTA ENTERA'!F81 -> 19955.4 | O16: 160
B17: 2
K18: TOTAL | M18: =+M16*O16/1000 -> 3192.864
B21: PESO DE LAVADO DE FILETE DE POTA POR CUADRILLA
B23: N° | C23: APELLIDOS Y NOMBRES | K23: MENÚ / CENA | M23: TOTAL (PESO) | O23: Importe s/.
B24: 1 | C24: =+C16 -> CUADRILLA FELIX | M24: =+M16*0.4 -> 7982.16 | O24: 150
B25: 2
K26: TOTAL | M26: =+M24*O24/1000 -> 1197.324
B29: PESO DE LIMPIEZA DE CONO DE POTA POR CUADRILLA
B31: N° | C31: APELLIDOS Y NOMBRES | K31: MENÚ / CENA | M31: TOTAL (PESO) | O31: Importe s/.
B32: 1 | C32: =+C24 -> CUADRILLA FELIX | M32: 130 | O32: 100
B33: 2
K34: TOTAL | M34: =+M32*O32/1000 -> 13
K36: TOTAL GENERAL | N36: =+M18+M26+M34 -> 4403.188
B37: OBSERVACIONES:
C43: V°B° Jefe de Producciòn | J43: V°B° Gerencia General
B45: RESPONSABLE DEL REGISTRO
B46: NOMBRE: | D46: =+D10 -> OMAR ESCOBEDO | K46: FECHA: | M46: =+G8 -> 46227
B47: CARGO | D47: SUPERVISOR DEL ÁREA DE FILETEO | K47: FIRMA:

Sheet CUADRILLA 2
E2: TAREO DE PERSONAL ÁREA DE FILETEROS | M2: Registro | O2: SPM-FOT-007
M3: Versión | O3: 1
M4: Fecha | O4: JULIO 2026
M5: Página | O5: 1
B7: CLIENTE: | D7: =+'POTA ENTERA'!E10 -> GLOBAL TOP FOOD PERÚ S.A.C. | J7: PRODUCTO: | M7: POTA ENTERA
B8: DÍA / FECHA: | D8: Viernes | F8: / | G8: =+'POTA ENTERA'!U11 -> 46227 | J8: TURNO: | M8: DÍA
B9: HORA INICIO: | F9: 7:00 am | J9: HORA TERMINO: | N9: 0.68402778
B10: SUPERVISOR: | D10: OMAR ESCOBEDO | J10: PLACA CARRO:
B13: PESO DE FILETEO POR CUADRILLA
B15: N° | C15: APELLIDOS Y NOMBRES | K15: MENÚ / CENA | M15: TOTAL (PESO) | O15: Importe s/.
B16: 1 | C16: =+'POTA ENTERA'!O81 -> CUADRILLA LUIS | M16: =+'POTA ENTERA'!Q81 -> 19971.8 | O16: 160
B17: 2
K18: TOTAL | M18: =+M16*O16/1000 -> 3195.488
B21: PESO DE LAVADO DE FILETE DE POTA POR CUADRILLA
B23: N° | C23: APELLIDOS Y NOMBRES | K23: MENÚ / CENA | M23: TOTAL (PESO) | O23: Importe s/.
B24: 1 | C24: =+C16 -> CUADRILLA LUIS | M24: =+M16*0.4 -> 7988.72 | O24: 150
B25: 2
K26: TOTAL | M26: =+M24*O24/1000 -> 1198.308
B29: PESO DE LIMPIEZA DE CONO DE POTA POR CUADRILLA
B31: N° | C31: APELLIDOS Y NOMBRES | K31: MENÚ / CENA | M31: TOTAL (PESO) | O31: Importe s/.
B32: 1 | C32: =+C24 -> CUADRILLA LUIS | M32: 130 | O32: 100
B33: 2
K34: TOTAL | M34: =+M32*O32/1000 -> 13
K36: TOTAL GENERAL | N36: =+M18+M26+M34 -> 4406.796
B37: OBSERVACIONES:
C43: V°B° Jefe de Producciòn | J43: V°B° Gerencia General
B45: RESPONSABLE DEL REGISTRO
B46: NOMBRE: | D46: =+D10 -> OMAR ESCOBEDO | K46: FECHA: | M46: =+G8 -> 46227
B47: CARGO | D47: SUPERVISOR DEL ÁREA DE FILETEO | K47: FIRMA:
