Workbook
Name LISTA: #REF!

Sheet NUQUERAS
M1: FECHA: | N1: 46223
C2: PESOS DE NUCAS | M2: HORA INICIO: | N2: 0.34722222
M3: HORA TÉRMINO:
B4: NUQUERAS
C5: DÍA | D5: Lunes | M5: PLACA: | N5: NUCA
A6: N° | B6: CUADRILLA | C6: CUADRILLA CHARLES
C7: Beatriz Vargas | D7: Angélica Sabino | E7: Vicmary Flores | F7: Fiorella Morales | G7: Denisse PAREDES | H7: Rosario Odicio | I7: Génesis López | J7: ROSENDA ALBA
A8: 1 | C8: 25.82 | D8: 25.88 | E8: 25.76 | F8: 25.68 | G8: 25.8 | H8: 25.98 | I8: 25.82 | J8: 25.98
A9: 2 | C9: 25.66 | D9: 25.34 | E9: 25.96 | F9: 25.98 | G9: 25.64 | H9: 25.88 | I9: 25.88 | J9: 25.68
A10: 3 | C10: 25.54 | D10: 25.14 | E10: 25.62 | F10: 25 | G10: 25.82 | H10: 25.72 | I10: 25.22 | J10: 25.98
A11: 4 | C11: 25.92 | D11: 25.42 | E11: 25.56 | F11: 25.66 | G11: 25.44 | H11: 25.12 | I11: 25.52 | J11: 25.78
A12: 5 | C12: 25.7 | D12: 25.64 | E12: 42.04 | F12: 25.92 | G12: 35.32 | H12: 25.98 | I12: 25.44 | J12: 25.69
A13: 6 | C13: 25.82 | D13: 25.66 | E13: 33.28 | F13: 25.92 | G13: 25.48 | H13: 25.5 | I13: 25.92 | J13: 42.5
A14: 7 | C14: 41.72 | D14: 38.28 | E14: 34.7 | F14: 38.2 | G14: 28.4 | H14: 31.68 | I14: 31.58 | J14: 41.96
A15: 8 | C15: 30.5 | D15: 28.94 | E15: 33.46 | F15: 30.36 | G15: 37.02 | H15: 34.94 | I15: 25.72 | J15: 48.96
A16: 9 | C16: 40.72 | D16: 32.92 | E16: 39.68 | F16: 29.72 | G16: 31.6 | H16: 35.06 | I16: 30.04 | J16: 42.36
A17: 10 | C17: 32 | D17: 29.36 | E17: 49.98 | F17: 38.96 | G17: 49.42 | H17: 37.28 | I17: 34.62 | J17: 52.48
A18: 11 | C18: 36.88 | D18: 30.58 | E18: 29.02 | F18: 27.86 | G18: 30.06 | H18: 40.24 | I18: 33.56 | J18: 47.85
A19: 113 | C19: 42.64 | D19: 34.44 | E19: 37.28 | F19: 24.22 | G19: 26.68 | H19: 35.08 | I19: 35.04 | J19: 25.36
... A21: 15 | C21: 34.86 | D21: 29 | E21: 34.38 | F21: 33.58 | G21: 42.5 | H21: 43.36 | I21: 30.58 | J21: 32.57
A22: 16 | C22: 36.6 | D22: 32.32 | E22: 28.94 | F22: 38.48 | H22: 38.1 | I22: 33.02 | J22: 45.69
A23: 17 | C23: 47.28 | D23: 31.4 | F23: 37.62 | H23: 50.1 | I23: 33.6
A24: 18 | C24: 36.22 | D24: 21.44 | H24: 4.84 | I24: 43.38
A25: 19 | C25: 32.92 | D25: 45.48 | I25: 37.9
A26: 20 | C26: 44 | D26: 29.48 | I26: 35
A27: 21
A28: 22
A29: 23
A30: 24
A31: 25
A32: 26
A33: 27
A34: 28
A35: 29
A36: 30
A37: 31
B38: =SUM(B8:B37) | C38: =SUM(C8:C37) | D38: =SUM(D8:D37) | E38: =SUM(E8:E37) | F38: =SUM(F8:F37) | G38: =SUM(G8:G37) | H38: =SUM(H8:H37) | I38: =SUM(I8:I37) | ... P38: =SUM(P8:P37)
B39: =SUM(B38:P38)
B43: CUADRILLA | C43: CUADRILLA PAZ
B44: ITEM | C44: Sara Cori | D44: Milagros Cori
...

Sheet  NUQUERAS omar 
M1: FECHA: | N1: 46223
C2: PESOS DE NUCAS | M2: HORA INICIO: | N2: 0.34722222
M3: HORA TÉRMINO:
B4: NUQUERAS
C5: DÍA | D5: Lunes | M5: PLACA: | N5: NUCA
A6: N° | B6: CUADRILLA | C6: OMAR
C7: Martina Quispe
A8: 1 | C8: 21.06
A9: 2 | C9: 30.12
A10: 3 | C10: 37.86
A11: 4 | C11: 30.94
A12: 5 | C12: 31.54
A13: 6 | C13: 47.26
A14: 7 | C14: 32.22
A15: 8 | C15: 34.98
A16: 9 | C16: 32.18
A17: 10
A18: 11
A19: 113
A20: 14
A21: 15
A22: 16
A23: 17
A24: 18
A25: 19
A26: 20
A27: 21
A28: 22
... A37: 31
B38: =SUM(B8:B37) | C38: =SUM(C8:C37) | D38: =SUM(D8:D37) | E38: =SUM(E8:E37) | F38: =SUM(F8:F37) | G38: =SUM(G8:G37) | H38: =SUM(H8:H37) | I38: =SUM(I8:I37) | ... P38: =SUM(P8:P37)
B39: =SUM(B38:P38)

Sheet TAREO CHARLES
E2: TAREO DE PERSONAL AREA DE NUCAS | M2: Registro | O2: SPM-FPO-009
M3: Versión | O3: 1
M4: Fecha | O4: MARZO 2026
M5: Página | O5: 1
B7: CLIENTE: | D7: GLOBAL TOP FOOD PERÚ S.A.C. | J7: PRODUCTO: | L7: POTA A GRANEL
B8: DÍA / FECHA: | D8: =+TEXT(F8,"dddd") | F8: =+NUQUERAS!N1 | J8: TURNO: | L8: =+NUQUERAS!C5
B9: HORA INICIO: | D9: =+NUQUERAS!N2 | J9: HORA TERMINO: | L9: =+NUQUERAS!N3
B10: SUPERVISOR 1: | D10: DANIELA RIVAS | J10: CUADRILLA | L10: CHARLES
B12: N° | C12: APELLIDOS Y NOMBRES | K12: MENÚ / CENA | M12: TOTAL (PESO) | O12: Importe s/.
B13: 1 | C13: =+NUQUERAS!C7 | M13: =+NUQUERAS!C38
B14: 2 | C14: =+NUQUERAS!D7 | M14: =+NUQUERAS!D38
B15: 3 | C15: =+NUQUERAS!E7 | K15: 1 | M15: =+NUQUERAS!E38
B16: 4 | C16: =+NUQUERAS!F7 | K16: 1 | M16: =+NUQUERAS!F38
B17: 5 | C17: =+NUQUERAS!G7 | M17: =+NUQUERAS!G38
B18: 6 | C18: =+NUQUERAS!H7 | M18: =+NUQUERAS!H38
B19: 7 | C19: =+NUQUERAS!I7 | K19: 1 | M19: =+NUQUERAS!I38
B20: 8 | C20: =+NUQUERAS!J7 | M20: =+NUQUERAS!J38
B21: 9
B22: 10
B23: 11
B24: 12
B25: 13
B26: 14
B27: 15
B28: 16
B29: 17
B30: 18
B31: 19
B32: 20
K33: TOTAL | M33: =SUM(M13:N32)
B34: OBSERVACIONES:
B36: * Especificar solo si son varios PRODUCTOS.
B37: RESUMEN: | C37: N° de PLACA / PRODUCTO * | G37: TOTAL RECIBIDO (KG) | K37: P.U. (S/.) | N37: IMPORTE TOTAL (S/.)
B38: 1 | C38: =+NUQUERAS!N5 | G38: =+M33
B39: 2
B40: 3
B41: TOTAL PROCESADO
C46: Responsable de Planilla | J46: V°B° Gerencia General
B48: RESPONSABLE DEL REGISTRO
B49: NOMBRE: | D49: =+D10 | K49: FECHA: | M49: =+F8
...

Sheet TAREO PAZ
E2: TAREO DE PERSONAL AREA DE NUCAS | M2: Registro | O2: SPM-FPO-009
M3: Versión | O3: 1
M4: Fecha | O4: MARZO 2026
M5: Página | O5: 1
B7: CLIENTE: | D7: GLOBAL TOP FOOD PERÚ S.A.C. | J7: PRODUCTO: | L7: POTA A GRANEL
B8: DÍA / FECHA: | D8: =+TEXT(F8,"dddd") | F8: =+NUQUERAS!N1 | J8: TURNO: | L8: =+NUQUERAS!C5
B9: HORA INICIO: | D9: =+NUQUERAS!N2 | J9: HORA TERMINO: | L9: =+NUQUERAS!N3
B10: SUPERVISOR 1: | D10: DANIELA RIVAS | J10: CUADRILLA | L10: PAZ
B12: N° | C12: APELLIDOS Y NOMBRES | K12: MENÚ / CENA | M12: TOTAL (PESO) | O12: Importe s/.
B13: 1 | C13: =+NUQUERAS!C44 | K13: 1 | M13: =+NUQUERAS!C72
B14: 2 | C14: =+NUQUERAS!D44 | K14: 1 | M14: =+NUQUERAS!D72
B15: 3
B16: 4
B17: 5
B18: 6
B19: 7
B20: 8
B21: 9
B22: 10
B23: 11
B24: 12
B25: 13
B26: 14
... B32: 20
K33: TOTAL | M33: =SUM(M13:N32)
B34: OBSERVACIONES:
B36: * Especificar solo si son varios PRODUCTOS.
B37: RESUMEN: | C37: N° de PLACA / PRODUCTO * | G37: TOTAL RECIBIDO (KG) | K37: P.U. (S/.) | N37: IMPORTE TOTAL (S/.)
B38: 1 | C38: =+NUQUERAS!N5 | G38: =+M33
B39: 2
B40: 3
B41: TOTAL PROCESADO
C46: Responsable de Planilla | J46: V°B° Gerencia General
B48: RESPONSABLE DEL REGISTRO
B49: NOMBRE: | D49: =+D10 | K49: FECHA: | M49: =+F8
B50: CARGO | D50: SUPERVISOR DE PRODUCCIÓN | K50: FIRMA:

Sheet TAREO OMAR
E2: TAREO DE PERSONAL AREA DE NUCAS | M2: Registro | O2: SPM-FPO-009
M3: Versión | O3: 1
M4: Fecha | O4: MARZO 2026
M5: Página | O5: 1
B7: CLIENTE: | D7: GLOBAL TOP FOOD PERÚ S.A.C. | J7: PRODUCTO: | L7: POTA A GRANEL
B8: DÍA / FECHA: | D8: =+TEXT(F8,"dddd") | F8: =+NUQUERAS!N1 | J8: TURNO: | L8: =+NUQUERAS!C5
B9: HORA INICIO: | D9: =+NUQUERAS!N2 | J9: HORA TERMINO: | L9: =+NUQUERAS!N3
B10: SUPERVISOR 1: | D10: DANIELA RIVAS | J10: CUADRILLA | L10: OMAR
B12: N° | C12: APELLIDOS Y NOMBRES | K12: MENÚ / CENA | M12: TOTAL (PESO) | O12: Importe s/.
B13: 1 | C13: Martina Quispe | K13: 1 | M13: 298.16
B14: 2
B15: 3
B16: 4
B17: 5
B18: 6
B19: 7
B20: 8
B21: 9
B22: 10
B23: 11
B24: 12
B25: 13
... B32: 20
K33: TOTAL | M33: =SUM(M13:N32)
B34: OBSERVACIONES:
B36: * Especificar solo si son varios PRODUCTOS.
B37: RESUMEN: | C37: N° de PLACA / PRODUCTO * | G37: TOTAL RECIBIDO (KG) | K37: P.U. (S/.) | N37: IMPORTE TOTAL (S/.)
B38: 1 | C38: =+NUQUERAS!N5 | G38: =+M33
B39: 2
B40: 3
B41: TOTAL PROCESADO
C46: Responsable de Planilla | J46: V°B° Gerencia General
B48: RESPONSABLE DEL REGISTRO
B49: NOMBRE: | D49: =+D10 | K49: FECHA: | M49: =+F8
B50: CARGO | D50: SUPERVISOR DE PRODUCCIÓN | K50: FIRMA:

Sheet TAREO CUADRILLA 4
E2: TAREO DE PERSONAL AREA DE NUCAS | M2: Registro | O2: SPM-FPO-009
M3: Versión | O3: 1
M4: Fecha | O4: MARZO 2026
M5: Página | O5: 1
B7: CLIENTE: | D7: GLOBAL TOP FOOD PERÚ S.A.C. | J7: PRODUCTO: | L7: POTA A GRANEL
B8: DÍA / FECHA: | D8: =+TEXT(F8,"dddd") | F8: =+NUQUERAS!N1 | J8: TURNO: | L8: =+NUQUERAS!C5
B9: HORA INICIO: | D9: =+NUQUERAS!N2 | J9: HORA TERMINO: | L9: =+NUQUERAS!N3
B10: SUPERVISOR 1: | D10: DANIELA RIVAS | J10: CUADRILLA | L10: CHARLES
B12: N° | C12: APELLIDOS Y NOMBRES | K12: MENÚ / CENA | M12: TOTAL (PESO) | O12: Importe s/.
B13: 1 | C13: =+NUQUERAS!C77 | M13: =+NUQUERAS!C108
B14: 2 | C14: =+NUQUERAS!D77 | M14: =+NUQUERAS!D108
B15: 3 | C15: =+NUQUERAS!E77 | K15: 1 | M15: =+NUQUERAS!E108
B16: 4 | C16: =+NUQUERAS!F77 | K16: 1 | M16: =+NUQUERAS!F108
B17: 5 | C17: =+NUQUERAS!G77 | M17: =+NUQUERAS!G108
B18: 6 | C18: =+NUQUERAS!H77 | M18: =+NUQUERAS!H108
B19: 7 | C19: =+NUQUERAS!I77 | K19: 1 | M19: =+NUQUERAS!I108
B20: 8 | C20: =+NUQUERAS!J77 | M20: =+NUQUERAS!J108
B21: 9
B22: 10
B23: 11
B24: 12
B25: 13
B26: 14
B27: 15
B28: 16
B29: 17
B30: 18
B31: 19
B32: 20
K33: TOTAL | M33: =SUM(M13:N32)
B34: OBSERVACIONES:
B36: * Especificar solo si son varios PRODUCTOS.
B37: RESUMEN: | C37: N° de PLACA / PRODUCTO * | G37: TOTAL RECIBIDO (KG) | K37: P.U. (S/.) | N37: IMPORTE TOTAL (S/.)
B38: 1 | C38: =+NUQUERAS!N5 | G38: =+M33
B39: 2
B40: 3
B41: TOTAL PROCESADO
C46: Responsable de Planilla | J46: V°B° Gerencia General
B48: RESPONSABLE DEL REGISTRO
B49: NOMBRE: | D49: =+D10 | K49: FECHA: | M49: =+F8
...

Sheet TAREO CUADRILLA 5
E2: TAREO DE PERSONAL AREA DE NUCAS | M2: Registro | O2: SPM-FPO-009
M3: Versión | O3: 1
M4: Fecha | O4: MARZO 2026
M5: Página | O5: 1
B7: CLIENTE: | D7: GLOBAL TOP FOOD PERÚ S.A.C. | J7: PRODUCTO: | L7: POTA A GRANEL
B8: DÍA / FECHA: | D8: =+TEXT(F8,"dddd") | F8: =+NUQUERAS!N1 | J8: TURNO: | L8: =+NUQUERAS!C5
B9: HORA INICIO: | D9: =+NUQUERAS!N2 | J9: HORA TERMINO: | L9: =+NUQUERAS!N3
B10: SUPERVISOR 1: | D10: DANIELA RIVAS | J10: CUADRILLA | L10: CHARLES
B12: N° | C12: APELLIDOS Y NOMBRES | K12: MENÚ / CENA | M12: TOTAL (PESO) | O12: Importe s/.
B13: 1 | C13: =+NUQUERAS!C114 | M13: =+NUQUERAS!C145
B14: 2 | C14: =+NUQUERAS!D114 | M14: =+NUQUERAS!D145
B15: 3 | C15: =+NUQUERAS!E114 | K15: 1 | M15: =+NUQUERAS!E145
B16: 4 | C16: =+NUQUERAS!F114 | K16: 1 | M16: =+NUQUERAS!F145
B17: 5 | C17: =+NUQUERAS!G114 | M17: =+NUQUERAS!G145
B18: 6 | C18: =+NUQUERAS!H114 | M18: =+NUQUERAS!H145
B19: 7 | C19: =+NUQUERAS!I114 | K19: 1 | M19: =+NUQUERAS!I145
B20: 8 | C20: =+NUQUERAS!J114 | M20: =+NUQUERAS!J145
B21: 9
B22: 10
B23: 11
B24: 12
B25: 13
B26: 14
B27: 15
B28: 16
B29: 17
B30: 18
B31: 19
B32: 20
K33: TOTAL | M33: =SUM(M13:N32)
B34: OBSERVACIONES:
B36: * Especificar solo si son varios PRODUCTOS.
B37: RESUMEN: | C37: N° de PLACA / PRODUCTO * | G37: TOTAL RECIBIDO (KG) | K37: P.U. (S/.) | N37: IMPORTE TOTAL (S/.)
B38: 1 | C38: =+NUQUERAS!N5 | G38: =+M33
B39: 2
B40: 3
B41: TOTAL PROCESADO
C46: Responsable de Planilla | J46: V°B° Gerencia General
B48: RESPONSABLE DEL REGISTRO
B49: NOMBRE: | D49: =+D10 | K49: FECHA: | M49: =+F8
...
